Workbook
Name DeliveryDays: Overall!$B$5
Name WorkingDaysPerMonth: Overall!$B$6
Name DeliveryMonths: Overall!$B$7
Name HoursPerMonth: Overall!$B$8
Name ProjectStart: Overall!$B$9
Name SprintDays: Overall!$B$10
Name HorizonYears: Overall!$B$11
Name CostEscalation: Overall!$B$12
Name HorizonFactor: Overall!$B$13
Name Contingency: Overall!$B$14
Name FxRate: Overall!$B$15
Name LastActual: Sprints!$C$3

Sheet Overall
A1: OCR Invoice Automation PoC: build and 5-year run
A2: All costs in USD. Cloud: Azure retail list prices in southeastasia fetched 2026-09-28, no discounts or reservations. Blue cells are inputs; black cells are formulas; green cells link to other sheets.
A3: Inputs
A4: Input | B4: Value
A5: Days of delivery (working days) | B5: 32
A6: Working days per month | B6: 21
A7: Months of delivery | B7: =DeliveryDays/WorkingDaysPerMonth
A8: Hours per month (always-on services) | B8: 730
A9: Delivery start date (optional; dates the epics and sprints)
A10: Working days per sprint | B10: 10
A11: Years of run after go-live (3 to 5) | B11: 5
A12: Yearly increase in run costs | B12: 0
A13: Run years, with the yearly increase | B13: =IF(CostEscalation=0,HorizonYears,((1+CostEscalation)^HorizonYears-1)/CostEscalation)
A14: Contingency | B14: 0
A15: Exchange rate (1 USD = x USD) | B15: 1
A17: Delivery team (build)
A18: Role | B18: Day rate (USD) | C18: Employees | D18: Days on delivery | E18: Allocation | F18: Mandays | G18: Cost (USD) | H18: Cited from
A19: Team member (blended) | B19: =VLOOKUP(A19,'Rate Card'!$A$5:$B$50,2,FALSE) | C19: 2 | D19: =DeliveryDays | E19: 1 | F19: =C19*D19*E19 | G19: =F19*B19 | H19: assumption: 2 people for 32 days (30 stories at ~1 story/day, AI-assisted, plus 2 days slack); Dj to confirm
B20: =IF(A20="","",VLOOKUP(A20,'Rate Card'!$A$5:$B$50,2,FALSE)) | F20: =IF(A20="","",C20*D20*E20) | G20: =IF(A20="","",F20*B20)
B21: =IF(A21="","",VLOOKUP(A21,'Rate Card'!$A$5:$B$50,2,FALSE)) | F21: =IF(A21="","",C21*D21*E21) | G21: =IF(A21="","",F21*B21)
B22: =IF(A22="","",VLOOKUP(A22,'Rate Card'!$A$5:$B$50,2,FALSE)) | F22: =IF(A22="","",C22*D22*E22) | G22: =IF(A22="","",F22*B22)
A23: Total | C23: =SUM(C19:C22) | F23: =SUM(F19:F22) | G23: =SUM(G19:G22)
A25: Run support (OPEX): IT support and maintenance after go-live
A26: Role | B26: Day rate (USD) | C26: Mandays per year | D26: Cost per year (USD) | E26: Cited from
A27: Team member (blended) | B27: =VLOOKUP(A27,'Rate Card'!$A$5:$B$50,2,FALSE) | C27: 12 | D27: =C27*B27 | E27: assumption: 1 day a month for patching, dependency upgrades, DB start/stop and alert triage; Dj to confirm
B28: =IF(A28="","",VLOOKUP(A28,'Rate Card'!$A$5:$B$50,2,FALSE)) | D28: =IF(A28="","",C28*B28)
B29: =IF(A29="","",VLOOKUP(A29,'Rate Card'!$A$5:$B$50,2,FALSE)) | D29: =IF(A29="","",C29*B29)
B30: =IF(A30="","",VLOOKUP(A30,'Rate Card'!$A$5:$B$50,2,FALSE)) | D30: =IF(A30="","",C30*B30)
A31: Total | C31: =SUM(C27:C30) | D31: =SUM(D27:D30)
A33: Cost summary
A34: Item | B34: Monthly (USD) | C34: Months in delivery | D34: Delivery cost (USD) | E34: Run months per year | F34: Run cost per year (USD) | G34: Run cost over the horizon (USD) | H34: Total (USD) | I34: From
A35: Shared environment | B35: ='Shared'!$I$12 | C35: =DeliveryMonths | D35: =B35*C35 | E35: 12 | F35: =B35*E35 | G35: =F35*HorizonFactor | H35: =D35+G35 | I35: Shared sheet
A36: Dev environment | B36: ='Dev'!$I$14 | C36: =DeliveryMonths | D36: =B36*C36 | E36: 12 | F36: =B36*E36 | G36: =F36*HorizonFactor | H36: =D36+G36 | I36: Dev sheet
A37: Prod environment | B37: ='Prod'!$I$14 | C37: =DeliveryMonths | D37: =B37*C37 | E37: 12 | F37: =B37*E37 | G37: =F37*HorizonFactor | H37: =D37+G37 | I37: Prod sheet
A38: Delivery team | D38: =G23 | H38: =D38+G38 | I38: Delivery team table above
A39: Run support (OPEX) | F39: =D31 | G39: =F39*HorizonFactor | H39: =D39+G39 | I39: Run support table above
A40: Recurring run costs | F40: ='Run Costs'!$C$8 | G40: =F40*HorizonFactor | H40: =D40+G40 | I40: Run Costs sheet
A41: Other one-off costs | D41: ='Other Costs'!$C$8 | H41: =D41+G41 | I41: Other Costs sheet
A42: Subtotal | D42: =SUM(D35:D41) | F42: =SUM(F35:F41) | G42: =SUM(G35:G41) | H42: =SUM(H35:H41)
A43: Contingency | D43: =D42*Contingency | F43: =F42*Contingency | G43: =G42*Contingency | H43: =D43+G43
...

Sheet Multi-Year
A1: Multi-year view
A2: In USD. Build is the delivery; each year after go-live carries the run costs, raised by the yearly increase, and the revenue given for it. Years past the horizon (Overall input) show zero. Contingency applies to every cost.
A4: Category | B4: Item | C4: Build | D4: Year 1 | E4: Year 2 | F4: Year 3 | G4: Year 4 | H4: Year 5 | I4: Total
A5: Revenue | B5: =IF('Revenue'!$B$5="","(spare revenue row)",'Revenue'!$B$5) | C5: 0 | D5: =IF(1<=HorizonYears,'Revenue'!D$5,0) | E5: =IF(2<=HorizonYears,'Revenue'!E$5,0) | F5: =IF(3<=HorizonYears,'Revenue'!F$5,0) | G5: =IF(4<=HorizonYears,'Revenue'!G$5,0) | H5: =IF(5<=HorizonYears,'Revenue'!H$5,0) | I5: =SUM(C5:H5)
A6: Revenue | B6: =IF('Revenue'!$B$6="","(spare revenue row)",'Revenue'!$B$6) | C6: 0 | D6: =IF(1<=HorizonYears,'Revenue'!D$6,0) | E6: =IF(2<=HorizonYears,'Revenue'!E$6,0) | F6: =IF(3<=HorizonYears,'Revenue'!F$6,0) | G6: =IF(4<=HorizonYears,'Revenue'!G$6,0) | H6: =IF(5<=HorizonYears,'Revenue'!H$6,0) | I6: =SUM(C6:H6)
A7: Revenue | B7: =IF('Revenue'!$B$7="","(spare revenue row)",'Revenue'!$B$7) | C7: 0 | D7: =IF(1<=HorizonYears,'Revenue'!D$7,0) | E7: =IF(2<=HorizonYears,'Revenue'!E$7,0) | F7: =IF(3<=HorizonYears,'Revenue'!F$7,0) | G7: =IF(4<=HorizonYears,'Revenue'!G$7,0) | H7: =IF(5<=HorizonYears,'Revenue'!H$7,0) | I7: =SUM(C7:H7)
A8: Cost | B8: Build: delivery team, environments during delivery, one-off costs | C8: ='Overall'!$D$42 | D8: 0 | E8: 0 | F8: 0 | G8: 0 | H8: 0 | I8: =SUM(C8:H8)
A9: Cost | B9: Shared environment (run) | C9: 0 | D9: =IF(1<=HorizonYears,'Overall'!$F$35*(1+CostEscalation)^0,0) | E9: =IF(2<=HorizonYears,'Overall'!$F$35*(1+CostEscalation)^1,0) | F9: =IF(3<=HorizonYears,'Overall'!$F$35*(1+CostEscalation)^2,0) | G9: =IF(4<=HorizonYears,'Overall'!$F$35*(1+CostEscalation)^3,0) | H9: =IF(5<=HorizonYears,'Overall'!$F$35*(1+CostEscalation)^4,0) | I9: =SUM(C9:H9)
A10: Cost | B10: Dev environment (run) | C10: 0 | D10: =IF(1<=HorizonYears,'Overall'!$F$36*(1+CostEscalation)^0,0) | E10: =IF(2<=HorizonYears,'Overall'!$F$36*(1+CostEscalation)^1,0) | F10: =IF(3<=HorizonYears,'Overall'!$F$36*(1+CostEscalation)^2,0) | G10: =IF(4<=HorizonYears,'Overall'!$F$36*(1+CostEscalation)^3,0) | H10: =IF(5<=HorizonYears,'Overall'!$F$36*(1+CostEscalation)^4,0) | I10: =SUM(C10:H10)
A11: Cost | B11: Prod environment (run) | C11: 0 | D11: =IF(1<=HorizonYears,'Overall'!$F$37*(1+CostEscalation)^0,0) | E11: =IF(2<=HorizonYears,'Overall'!$F$37*(1+CostEscalation)^1,0) | F11: =IF(3<=HorizonYears,'Overall'!$F$37*(1+CostEscalation)^2,0) | G11: =IF(4<=HorizonYears,'Overall'!$F$37*(1+CostEscalation)^3,0) | H11: =IF(5<=HorizonYears,'Overall'!$F$37*(1+CostEscalation)^4,0) | I11: =SUM(C11:H11)
A12: Cost | B12: Run support (OPEX) | C12: 0 | D12: =IF(1<=HorizonYears,'Overall'!$F$39*(1+CostEscalation)^0,0) | E12: =IF(2<=HorizonYears,'Overall'!$F$39*(1+CostEscalation)^1,0) | F12: =IF(3<=HorizonYears,'Overall'!$F$39*(1+CostEscalation)^2,0) | G12: =IF(4<=HorizonYears,'Overall'!$F$39*(1+CostEscalation)^3,0) | H12: =IF(5<=HorizonYears,'Overall'!$F$39*(1+CostEscalation)^4,0) | I12: =SUM(C12:H12)
A13: Cost | B13: Recurring run costs | C13: 0 | D13: =IF(1<=HorizonYears,'Overall'!$F$40*(1+CostEscalation)^0,0) | E13: =IF(2<=HorizonYears,'Overall'!$F$40*(1+CostEscalation)^1,0) | F13: =IF(3<=HorizonYears,'Overall'!$F$40*(1+CostEscalation)^2,0) | G13: =IF(4<=HorizonYears,'Overall'!$F$40*(1+CostEscalation)^3,0) | H13: =IF(5<=HorizonYears,'Overall'!$F$40*(1+CostEscalation)^4,0) | I13: =SUM(C13:H13)
A14: Contingency | B14: Contingency on every cost | C14: =SUMIF($A$5:$A$13,"Cost",C5:C13)*Contingency | D14: =SUMIF($A$5:$A$13,"Cost",D5:D13)*Contingency | E14: =SUMIF($A$5:$A$13,"Cost",E5:E13)*Contingency | F14: =SUMIF($A$5:$A$13,"Cost",F5:F13)*Contingency | G14: =SUMIF($A$5:$A$13,"Cost",G5:G13)*Contingency | H14: =SUMIF($A$5:$A$13,"Cost",H5:H13)*Contingency | I14: =SUM(C14:H14)
A15: Total revenue | C15: =SUMIF($A$5:$A$14,"Revenue",C5:C14) | D15: =SUMIF($A$5:$A$14,"Revenue",D5:D14) | E15: =SUMIF($A$5:$A$14,"Revenue",E5:E14) | F15: =SUMIF($A$5:$A$14,"Revenue",F5:F14) | G15: =SUMIF($A$5:$A$14,"Revenue",G5:G14) | H15: =SUMIF($A$5:$A$14,"Revenue",H5:H14) | I15: =SUMIF($A$5:$A$14,"Revenue",I5:I14)
A16: Total costs | C16: =SUMIF($A$5:$A$14,"Cost",C5:C14)+SUMIF($A$5:$A$14,"Contingency",C5:C14) | D16: =SUMIF($A$5:$A$14,"Cost",D5:D14)+SUMIF($A$5:$A$14,"Contingency",D5:D14) | E16: =SUMIF($A$5:$A$14,"Cost",E5:E14)+SUMIF($A$5:$A$14,"Contingency",E5:E14) | F16: =SUMIF($A$5:$A$14,"Cost",F5:F14)+SUMIF($A$5:$A$14,"Contingency",F5:F14) | G16: =SUMIF($A$5:$A$14,"Cost",G5:G14)+SUMIF($A$5:$A$14,"Contingency",G5:G14) | H16: =SUMIF($A$5:$A$14,"Cost",H5:H14)+SUMIF($A$5:$A$14,"Contingency",H5:H14) | I16: =SUMIF($A$5:$A$14,"Cost",I5:I14)+SUMIF($A$5:$A$14,"Contingency",I5:I14)
A17: Net | C17: =C15-C16 | D17: =D15-D16 | E17: =E15-E16 | F17: =F15-F16 | G17: =G15-G16 | H17: =H15-H16 | I17: =I15-I16
A18: Cumulative net | C18: =C17 | D18: =C18+D17 | E18: =D18+E17 | F18: =E18+F17 | G18: =F18+G17 | H18: =G18+H17 | I18: =H18
A20: Payback | B20: =IF(C18>=0,"Build",IF(D18>=0,"Year 1",IF(E18>=0,"Year 2",IF(F18>=0,"Year 3",IF(G18>=0,"Year 4",IF(H18>=0,"Year 5","beyond the horizon"))))))
A21: Return on cost (net / costs) | B21: =IF(I16=0,"",I17/I16)

Sheet Epics
A1: Epics: deliverables, forecast and actual
A2: In USD. Forecast: each epic takes a share of the build in proportion to its planned working days (that share of the delivery team and of the environments during delivery), plus the one-off costs tagged to it and its Claude API budget; dates run the epics one after another from the delivery start date. Actual: enter or keep the actual start and end dates; actual working days, the Claude API actual from the ledger, and team and infra scaled by actual / planned days (same team and rates) unless you enter the timesheet team cost. Blue cells are inputs; add an epic in a spare row.
A4: Epic | B4: Name | C4: Deliverables | D4: Planned days | E4: Planned weeks | F4: Planned start | G4: Planned end | H4: Share of build | I4: Team mandays | J4: Team cost (USD) | K4: Infra cost (USD) | L4: Other costs (USD) | M4: Claude API budget (USD) | N4: Forecast total (USD) | O4: Actual start | P4: Actual end | Q4: Actual days | R4: Days variance | S4: Days variance % | T4: Claude API actual (USD) | U4: Actual team cost, timesheets (USD) | V4: Actual total (USD) | W4: Cost variance (USD) | X4: Cited from
A5: 1 | B5: Suppliers can upload invoices by link | C5: Stories 1.1-1.9: Terraform, CI/CD, API and web skeletons, monitoring, supplier links, upload, device quality check | D5: 9 | E5: =IF(D5="","",D5/5) | F5: =IF(OR(D5="",ProjectStart=""),"",ProjectStart) | G5: =IF(F5="","",WORKDAY(F5,D5-1)) | H5: =IF(D5="","",D5/SUM($D$5:$D$12)) | I5: =IF(D5="","",H5*'Overall'!$F$23) | J5: =IF(D5="","",H5*'Overall'!$G$23) | K5: =IF(D5="","",H5*('Overall'!$D$35+'Overall'!$D$36+'Overall'!$D$37)) | L5: =IF(A5="","",SUMIFS('Other Costs'!$C$5:$C$7,'Other Costs'!$F$5:$F$7,A5)) | M5: 54 | N5: =IF(D5="","",J5+K5+L5+N(M5)) | Q5: =IF(OR(D5="",O5="",P5=""),"",NETWORKDAYS(O5,P5)) | R5: =IF(Q5="","",Q5-D5) | S5: =IF(Q5="","",Q5/D5-1) | V5: =IF(Q5="","",IF(U5="",J5*Q5/D5,U5)+K5*Q5/D5+L5+N(T5)) | W5: =IF(V5="","",V5-N5) | X5: _bmad-output/planning-artifacts/epics.md Epic 1: Suppliers can upload invoices by link
A6: 2 | B6: Invoices are read and checked automatically | C6: Stories 2.1-2.11: quality stage, pipeline recovery, DI extraction, PO sim, validation, staff sign-in, admin queue | D6: 11 | E6: =IF(D6="","",D6/5) | F6: =IF(OR(D6="",ProjectStart=""),"",WORKDAY(G5,1)) | G6: =IF(F6="","",WORKDAY(F6,D6-1)) | H6: =IF(D6="","",D6/SUM($D$5:$D$12)) | I6: =IF(D6="","",H6*'Overall'!$F$23) | J6: =IF(D6="","",H6*'Overall'!$G$23) | K6: =IF(D6="","",H6*('Overall'!$D$35+'Overall'!$D$36+'Overall'!$D$37)) | L6: =IF(A6="","",SUMIFS('Other Costs'!$C$5:$C$7,'Other Costs'!$F$5:$F$7,A6)) | M6: 66 | N6: =IF(D6="","",J6+K6+L6+N(M6)) | Q6: =IF(OR(D6="",O6="",P6=""),"",NETWORKDAYS(O6,P6)) | R6: =IF(Q6="","",Q6-D6) | S6: =IF(Q6="","",Q6/D6-1) | V6: =IF(Q6="","",IF(U6="",J6*Q6/D6,U6)+K6*Q6/D6+L6+N(T6)) | W6: =IF(V6="","",V6-N6) | X6: _bmad-output/planning-artifacts/epics.md Epic 2: Invoices are read and checked automatically
A7: 3 | B7: Clean invoices post to the accounts system | C7: Stories 3.1-3.4: accounts sim, auto-post, admin approve, search | D7: 4 | E7: =IF(D7="","",D7/5) | F7: =IF(OR(D7="",ProjectStart=""),"",WORKDAY(G6,1)) | G7: =IF(F7="","",WORKDAY(F7,D7-1)) | H7: =IF(D7="","",D7/SUM($D$5:$D$12)) | I7: =IF(D7="","",H7*'Overall'!$F$23) | J7: =IF(D7="","",H7*'Overall'!$G$23) | K7: =IF(D7="","",H7*('Overall'!$D$35+'Overall'!$D$36+'Overall'!$D$37)) | L7: =IF(A7="","",SUMIFS('Other Costs'!$C$5:$C$7,'Other Costs'!$F$5:$F$7,A7)) | M7: 24 | N7: =IF(D7="","",J7+K7+L7+N(M7)) | Q7: =IF(OR(D7="",O7="",P7=""),"",NETWORKDAYS(O7,P7)) | R7: =IF(Q7="","",Q7-D7) | S7: =IF(Q7="","",Q7/D7-1) | V7: =IF(Q7="","",IF(U7="",J7*Q7/D7,U7)+K7*Q7/D7+L7+N(T7)) | W7: =IF(V7="","",V7-N7) | X7: _bmad-output/planning-artifacts/epics.md Epic 3: Clean invoices post to the accounts system automatically
A8: 4 | B8: Deliveries tracked, overdue suppliers reminded | C8: Stories 4.1-4.4: goods-in scan, overdue list, reminders, delivery dates page | D8: 3 | E8: =IF(D8="","",D8/5) | F8: =IF(OR(D8="",ProjectStart=""),"",WORKDAY(G7,1)) | G8: =IF(F8="","",WORKDAY(F8,D8-1)) | H8: =IF(D8="","",D8/SUM($D$5:$D$12)) | I8: =IF(D8="","",H8*'Overall'!$F$23) | J8: =IF(D8="","",H8*'Overall'!$G$23) | K8: =IF(D8="","",H8*('Overall'!$D$35+'Overall'!$D$36+'Overall'!$D$37)) | L8: =IF(A8="","",SUMIFS('Other Costs'!$C$5:$C$7,'Other Costs'!$F$5:$F$7,A8)) | M8: 30 | N8: =IF(D8="","",J8+K8+L8+N(M8)) | Q8: =IF(OR(D8="",O8="",P8=""),"",NETWORKDAYS(O8,P8)) | R8: =IF(Q8="","",Q8-D8) | S8: =IF(Q8="","",Q8/D8-1) | V8: =IF(Q8="","",IF(U8="",J8*Q8/D8,U8)+K8*Q8/D8+L8+N(T8)) | W8: =IF(V8="","",V8-N8) | X8: _bmad-output/planning-artifacts/epics.md Epic 4: Deliveries are tracked, and overdue suppliers are reminded
A9: 5 | B9: Supplier price and speed insights | C9: Stories 5.1-5.6: analytics refresh, alert emails, price comparison, watchlist, scorecard, finance view | D9: 5 | E9: =IF(D9="","",D9/5) | F9: =IF(OR(D9="",ProjectStart=""),"",WORKDAY(G8,1)) | G9: =IF(F9="","",WORKDAY(F9,D9-1)) | H9: =IF(D9="","",D9/SUM($D$5:$D$12)) | I9: =IF(D9="","",H9*'Overall'!$F$23) | J9: =IF(D9="","",H9*'Overall'!$G$23) | K9: =IF(D9="","",H9*('Overall'!$D$35+'Overall'!$D$36+'Overall'!$D$37)) | L9: =IF(A9="","",SUMIFS('Other Costs'!$C$5:$C$7,'Other Costs'!$F$5:$F$7,A9)) | M9: 36 | N9: =IF(D9="","",J9+K9+L9+N(M9)) | Q9: =IF(OR(D9="",O9="",P9=""),"",NETWORKDAYS(O9,P9)) | R9: =IF(Q9="","",Q9-D9) | S9: =IF(Q9="","",Q9/D9-1) | V9: =IF(Q9="","",IF(U9="",J9*Q9/D9,U9)+K9*Q9/D9+L9+N(T9)) | W9: =IF(V9="","",V9-N9) | X9: _bmad-output/planning-artifacts/epics.md Epic 5: Finance and procurement see supplier price and speed insights
E10: =IF(D10="","",D10/5) | F10: =IF(OR(D10="",ProjectStart=""),"",WORKDAY(G9,1)) | G10: =IF(F10="","",WORKDAY(F10,D10-1)) | H10: =IF(D10="","",D10/SUM($D$5:$D$12)) | I10: =IF(D10="","",H10*'Overall'!$F$23) | J10: =IF(D10="","",H10*'Overall'!$G$23) | K10: =IF(D10="","",H10*('Overall'!$D$35+'Overall'!$D$36+'Overall'!$D$37)) | L10: =IF(A10="","",SUMIFS('Other Costs'!$C$5:$C$7,'Other Costs'!$F$5:$F$7,A10)) | N10: =IF(D10="","",J10+K10+L10+N(M10)) | Q10: =IF(OR(D10="",O10="",P10=""),"",NETWORKDAYS(O10,P10)) | R10: =IF(Q10="","",Q10-D10) | S10: =IF(Q10="","",Q10/D10-1) | V10: =IF(Q10="","",IF(U10="",J10*Q10/D10,U10)+K10*Q10/D10+L10+N(T10)) | W10: =IF(V10="","",V10-N10)
E11: =IF(D11="","",D11/5) | F11: =IF(OR(D11="",ProjectStart=""),"",WORKDAY(G10,1)) | G11: =IF(F11="","",WORKDAY(F11,D11-1)) | H11: =IF(D11="","",D11/SUM($D$5:$D$12)) | I11: =IF(D11="","",H11*'Overall'!$F$23) | J11: =IF(D11="","",H11*'Overall'!$G$23) | K11: =IF(D11="","",H11*('Overall'!$D$35+'Overall'!$D$36+'Overall'!$D$37)) | L11: =IF(A11="","",SUMIFS('Other Costs'!$C$5:$C$7,'Other Costs'!$F$5:$F$7,A11)) | N11: =IF(D11="","",J11+K11+L11+N(M11)) | Q11: =IF(OR(D11="",O11="",P11=""),"",NETWORKDAYS(O11,P11)) | R11: =IF(Q11="","",Q11-D11) | S11: =IF(Q11="","",Q11/D11-1) | V11: =IF(Q11="","",IF(U11="",J11*Q11/D11,U11)+K11*Q11/D11+L11+N(T11)) | W11: =IF(V11="","",V11-N11)
E12: =IF(D12="","",D12/5) | F12: =IF(OR(D12="",ProjectStart=""),"",WORKDAY(G11,1)) | G12: =IF(F12="","",WORKDAY(F12,D12-1)) | H12: =IF(D12="","",D12/SUM($D$5:$D$12)) | I12: =IF(D12="","",H12*'Overall'!$F$23) | J12: =IF(D12="","",H12*'Overall'!$G$23) | K12: =IF(D12="","",H12*('Overall'!$D$35+'Overall'!$D$36+'Overall'!$D$37)) | L12: =IF(A12="","",SUMIFS('Other Costs'!$C$5:$C$7,'Other Costs'!$F$5:$F$7,A12)) | N12: =IF(D12="","",J12+K12+L12+N(M12)) | Q12: =IF(OR(D12="",O12="",P12=""),"",NETWORKDAYS(O12,P12)) | R12: =IF(Q12="","",Q12-D12) | S12: =IF(Q12="","",Q12/D12-1) | V12: =IF(Q12="","",IF(U12="",J12*Q12/D12,U12)+K12*Q12/D12+L12+N(T12)) | W12: =IF(V12="","",V12-N12)
A13: Total | D13: =SUM(D5:D12) | I13: =SUM(I5:I12) | J13: =SUM(J5:J12) | K13: =SUM(K5:K12) | L13: =SUM(L5:L12) | M13: =SUM(M5:M12) | N13: =SUM(N5:N12) | Q13: =SUM(Q5:Q12) | R13: =SUM(R5:R12) | S13: =IF(Q13=0,"",Q13/SUMIFS(D5:D12,Q5:Q12,">0")-1) | T13: =SUM(T5:T12) | U13: =SUM(U5:U12) | V13: =SUM(V5:V12) | W13: =SUM(W5:W12)
A15: =IF(D13=DeliveryDays,"The planned epics add up to the days of delivery.","The planned epics add up to "&D13&" working days; the days of delivery input is "&DeliveryDays&". Costs are shared by planned epic days either way.")

Sheet Sprints
A1: Sprints: forecast and actual
A2: In USD. Every sprint is a timebox of the Overall input 'Working days per sprint' from the delivery start date. Forecast: the sprint's planned working days (the days of delivery, sprint by sprint) at the delivery team's and the environments' daily cost, plus any Claude API budget. Actual, up to the last actual activity (the latest completed story or day of Claude usage): the days worked in the sprint, the stories completed, the Claude API cost on its days, and the team at the days worked unless timesheets are entered. Sprints past the plan appear when work ran over. Blue cells are inputs.
A3: Last actual activity
A4: Sprint | B4: Start | C4: End | D4: Planned days | E4: Planned stories | F4: Team cost (USD) | G4: Infra cost (USD) | H4: Claude API budget (USD) | I4: Forecast total (USD) | J4: Days worked | K4: Stories done | L4: Stories done (list) | M4: Claude API actual (USD) | N4: Actual team cost, timesheets (USD) | O4: Actual total (USD) | P4: Cost variance (USD)
A5: 1 | B5: =IF(OR(D5="",ProjectStart=""),"",WORKDAY(ProjectStart,(1-1)*SprintDays)) | C5: =IF(B5="","",WORKDAY(B5,SprintDays-1)) | D5: =IF(OR(MIN(SprintDays,MAX(0,DeliveryDays-(1-1)*SprintDays))>0,AND(ProjectStart<>"",LastActual<>"",WORKDAY(ProjectStart,(1-1)*SprintDays)<=N(LastActual))),MIN(SprintDays,MAX(0,DeliveryDays-(1-1)*SprintDays)),"") | F5: =IF(D5="","",D5*'Overall'!$G$23/DeliveryDays) | G5: =IF(D5="","",D5*('Overall'!$D$35+'Overall'!$D$36+'Overall'!$D$37)/DeliveryDays) | I5: =IF(D5="","",F5+G5+N(H5)) | J5: =IF(OR(B5="",LastActual="",B5>N(LastActual)),"",NETWORKDAYS(B5,MIN(C5,LastActual))) | O5: =IF(J5="","",IF(N5="",J5*'Overall'!$G$23/DeliveryDays,N5)+J5*('Overall'!$D$35+'Overall'!$D$36+'Overall'!$D$37)/DeliveryDays+N(M5)) | P5: =IF(O5="","",O5-N(I5))
A6: 2 | B6: =IF(OR(D6="",ProjectStart=""),"",WORKDAY(ProjectStart,(2-1)*SprintDays)) | C6: =IF(B6="","",WORKDAY(B6,SprintDays-1)) | D6: =IF(OR(MIN(SprintDays,MAX(0,DeliveryDays-(2-1)*SprintDays))>0,AND(ProjectStart<>"",LastActual<>"",WORKDAY(ProjectStart,(2-1)*SprintDays)<=N(LastActual))),MIN(SprintDays,MAX(0,DeliveryDays-(2-1)*SprintDays)),"") | F6: =IF(D6="","",D6*'Overall'!$G$23/DeliveryDays) | G6: =IF(D6="","",D6*('Overall'!$D$35+'Overall'!$D$36+'Overall'!$D$37)/DeliveryDays) | I6: =IF(D6="","",F6+G6+N(H6)) | J6: =IF(OR(B6="",LastActual="",B6>N(LastActual)),"",NETWORKDAYS(B6,MIN(C6,LastActual))) | O6: =IF(J6="","",IF(N6="",J6*'Overall'!$G$23/DeliveryDays,N6)+J6*('Overall'!$D$35+'Overall'!$D$36+'Overall'!$D$37)/DeliveryDays+N(M6)) | P6: =IF(O6="","",O6-N(I6))
A7: 3 | B7: =IF(OR(D7="",ProjectStart=""),"",WORKDAY(ProjectStart,(3-1)*SprintDays)) | C7: =IF(B7="","",WORKDAY(B7,SprintDays-1)) | D7: =IF(OR(MIN(SprintDays,MAX(0,DeliveryDays-(3-1)*SprintDays))>0,AND(ProjectStart<>"",LastActual<>"",WORKDAY(ProjectStart,(3-1)*SprintDays)<=N(LastActual))),MIN(SprintDays,MAX(0,DeliveryDays-(3-1)*SprintDays)),"") | F7: =IF(D7="","",D7*'Overall'!$G$23/DeliveryDays) | G7: =IF(D7="","",D7*('Overall'!$D$35+'Overall'!$D$36+'Overall'!$D$37)/DeliveryDays) | I7: =IF(D7="","",F7+G7+N(H7)) | J7: =IF(OR(B7="",LastActual="",B7>N(LastActual)),"",NETWORKDAYS(B7,MIN(C7,LastActual))) | O7: =IF(J7="","",IF(N7="",J7*'Overall'!$G$23/DeliveryDays,N7)+J7*('Overall'!$D$35+'Overall'!$D$36+'Overall'!$D$37)/DeliveryDays+N(M7)) | P7: =IF(O7="","",O7-N(I7))
A8: 4 | B8: =IF(OR(D8="",ProjectStart=""),"",WORKDAY(ProjectStart,(4-1)*SprintDays)) | C8: =IF(B8="","",WORKDAY(B8,SprintDays-1)) | D8: =IF(OR(MIN(SprintDays,MAX(0,DeliveryDays-(4-1)*SprintDays))>0,AND(ProjectStart<>"",LastActual<>"",WORKDAY(ProjectStart,(4-1)*SprintDays)<=N(LastActual))),MIN(SprintDays,MAX(0,DeliveryDays-(4-1)*SprintDays)),"") | F8: =IF(D8="","",D8*'Overall'!$G$23/DeliveryDays) | G8: =IF(D8="","",D8*('Overall'!$D$35+'Overall'!$D$36+'Overall'!$D$37)/DeliveryDays) | I8: =IF(D8="","",F8+G8+N(H8)) | J8: =IF(OR(B8="",LastActual="",B8>N(LastActual)),"",NETWORKDAYS(B8,MIN(C8,LastActual))) | O8: =IF(J8="","",IF(N8="",J8*'Overall'!$G$23/DeliveryDays,N8)+J8*('Overall'!$D$35+'Overall'!$D$36+'Overall'!$D$37)/DeliveryDays+N(M8)) | P8: =IF(O8="","",O8-N(I8))
A9: 5 | B9: =IF(OR(D9="",ProjectStart=""),"",WORKDAY(ProjectStart,(5-1)*SprintDays)) | C9: =IF(B9="","",WORKDAY(B9,SprintDays-1)) | D9: =IF(OR(MIN(SprintDays,MAX(0,DeliveryDays-(5-1)*SprintDays))>0,AND(ProjectStart<>"",LastActual<>"",WORKDAY(ProjectStart,(5-1)*SprintDays)<=N(LastActual))),MIN(SprintDays,MAX(0,DeliveryDays-(5-1)*SprintDays)),"") | F9: =IF(D9="","",D9*'Overall'!$G$23/DeliveryDays) | G9: =IF(D9="","",D9*('Overall'!$D$35+'Overall'!$D$36+'Overall'!$D$37)/DeliveryDays) | I9: =IF(D9="","",F9+G9+N(H9)) | J9: =IF(OR(B9="",LastActual="",B9>N(LastActual)),"",NETWORKDAYS(B9,MIN(C9,LastActual))) | O9: =IF(J9="","",IF(N9="",J9*'Overall'!$G$23/DeliveryDays,N9)+J9*('Overall'!$D$35+'Overall'!$D$36+'Overall'!$D$37)/DeliveryDays+N(M9)) | P9: =IF(O9="","",O9-N(I9))
A10: 6 | B10: =IF(OR(D10="",ProjectStart=""),"",WORKDAY(ProjectStart,(6-1)*SprintDays)) | C10: =IF(B10="","",WORKDAY(B10,SprintDays-1)) | D10: =IF(OR(MIN(SprintDays,MAX(0,DeliveryDays-(6-1)*SprintDays))>0,AND(ProjectStart<>"",LastActual<>"",WORKDAY(ProjectStart,(6-1)*SprintDays)<=N(LastActual))),MIN(SprintDays,MAX(0,DeliveryDays-(6-1)*SprintDays)),"") | F10: =IF(D10="","",D10*'Overall'!$G$23/DeliveryDays) | G10: =IF(D10="","",D10*('Overall'!$D$35+'Overall'!$D$36+'Overall'!$D$37)/DeliveryDays) | I10: =IF(D10="","",F10+G10+N(H10)) | J10: =IF(OR(B10="",LastActual="",B10>N(LastActual)),"",NETWORKDAYS(B10,MIN(C10,LastActual))) | O10: =IF(J10="","",IF(N10="",J10*'Overall'!$G$23/DeliveryDays,N10)+J10*('Overall'!$D$35+'Overall'!$D$36+'Overall'!$D$37)/DeliveryDays+N(M10)) | P10: =IF(O10="","",O10-N(I10))
A11: 7 | B11: =IF(OR(D11="",ProjectStart=""),"",WORKDAY(ProjectStart,(7-1)*SprintDays)) | C11: =IF(B11="","",WORKDAY(B11,SprintDays-1)) | D11: =IF(OR(MIN(SprintDays,MAX(0,DeliveryDays-(7-1)*SprintDays))>0,AND(ProjectStart<>"",LastActual<>"",WORKDAY(ProjectStart,(7-1)*SprintDays)<=N(LastActual))),MIN(SprintDays,MAX(0,DeliveryDays-(7-1)*SprintDays)),"") | F11: =IF(D11="","",D11*'Overall'!$G$23/DeliveryDays) | G11: =IF(D11="","",D11*('Overall'!$D$35+'Overall'!$D$36+'Overall'!$D$37)/DeliveryDays) | I11: =IF(D11="","",F11+G11+N(H11)) | J11: =IF(OR(B11="",LastActual="",B11>N(LastActual)),"",NETWORKDAYS(B11,MIN(C11,LastActual))) | O11: =IF(J11="","",IF(N11="",J11*'Overall'!$G$23/DeliveryDays,N11)+J11*('Overall'!$D$35+'Overall'!$D$36+'Overall'!$D$37)/DeliveryDays+N(M11)) | P11: =IF(O11="","",O11-N(I11))
A12: Total | D12: =SUM(D5:D11) | F12: =SUM(F5:F11) | G12: =SUM(G5:G11) | H12: =SUM(H5:H11) | I12: =SUM(I5:I11) | J12: =SUM(J5:J11) | K12: =SUM(K5:K11) | M12: =SUM(M5:M11) | N12: =SUM(N5:N11) | O12: =SUM(O5:O11) | P12: =SUM(P5:P11)

Sheet Phase Budgets
A1: Phase budgets: Claude API budget and actual per planning phase
A2: In USD, at Claude API list prices. The budget each planning phase may spend (test design, governance, diagrams, course corrections ...), set once the epics and sprint plan are done; the epics and sprints carry their own budgets on their sheets. Actual: the phase's Claude cost from the ledger (Claude Usage Detail) once the close-out sheets are in. A control figure: not added to any total. Blue cells are inputs; name a phase as the token ledger does.
A4: Phase | B4: Claude API budget (USD) | C4: Claude API actual (USD) | D4: Variance (USD) | E4: Variance % | F4: Cited from
A5: planning changes (correct course) | B5: 10 | D5: =IF(OR(A5="",C5=""),"",C5-N(B5)) | E5: =IF(OR(D5="",N(B5)=0),"",C5/B5-1) | F5: owner: Dj, 2026-09-28
A6: test design | B6: 8 | D6: =IF(OR(A6="",C6=""),"",C6-N(B6)) | E6: =IF(OR(D6="",N(B6)=0),"",C6/B6-1) | F6: owner: Dj, 2026-09-28
A7: merges, promotions & deploys | B7: 5 | D7: =IF(OR(A7="",C7=""),"",C7-N(B7)) | E7: =IF(OR(D7="",N(B7)=0),"",C7/B7-1) | F7: owner: Dj, 2026-09-28
A8: governance (Jules) | B8: 5 | D8: =IF(OR(A8="",C8=""),"",C8-N(B8)) | E8: =IF(OR(D8="",N(B8)=0),"",C8/B8-1) | F8: owner: Dj, 2026-09-28
A9: architecture docs (Da Vinci) | B9: 4 | D9: =IF(OR(A9="",C9=""),"",C9-N(B9)) | E9: =IF(OR(D9="",N(B9)=0),"",C9/B9-1) | F9: owner: Dj, 2026-09-28
A10: token reporting | B10: 2 | D10: =IF(OR(A10="",C10=""),"",C10-N(B10)) | E10: =IF(OR(D10="",N(B10)=0),"",C10/B10-1) | F10: owner: Dj, 2026-09-28
D11: =IF(OR(A11="",C11=""),"",C11-N(B11)) | E11: =IF(OR(D11="",N(B11)=0),"",C11/B11-1)
D12: =IF(OR(A12="",C12=""),"",C12-N(B12)) | E12: =IF(OR(D12="",N(B12)=0),"",C12/B12-1)
D13: =IF(OR(A13="",C13=""),"",C13-N(B13)) | E13: =IF(OR(D13="",N(B13)=0),"",C13/B13-1)
A14: Total | B14: =SUM(B5:B13) | C14: =SUM(C5:C13) | D14: =SUM(D5:D13)

Sheet Revenue
A1: Revenue
A2: Revenue the solution earns, per year after go-live, in USD, from the owner or the business case; each stream cites its source. Years past the horizon are ignored. Blue cells are inputs.
A4: # | B4: Stream | C4: Basis | D4: Year 1 | E4: Year 2 | F4: Year 3 | G4: Year 4 | H4: Year 5 | I4: Cited from | J4: Note
A8: Total | D8: =SUM(D5:D7) | E8: =SUM(E5:E7) | F8: =SUM(F5:F7) | G8: =SUM(G5:G7) | H8: =SUM(H5:H7)

Sheet Rate Card
A1: Employee rate card
A2: Day rates in USD. Source: Dj, in chat 2026-09-28: blended average day rate; updated 2026-09-28. Blue cells are inputs; the team and support tables look roles up here.
A4: Role | B4: Day rate (USD) | C4: Note
A5: Team member (blended) | B5: 800 | C5: average across roles

Sheet Other Costs
A1: Other one-off costs
A2: Licences, tests, training and other one-off costs of the build, outside the environments and the team, in USD.
A4: # | B4: Item | C4: Amount (USD) | D4: Cited from | E4: Note | F4: Epic
A8: Total | C8: =SUM(C5:C7)

Sheet Run Costs
A1: Recurring run costs (OPEX)
A2: Yearly costs of running the solution outside the cloud environments and the support team: support contracts, licences, subscriptions. In USD per year; the Multi-Year sheet escalates them by the yearly increase.
A4: # | B4: Item | C4: Annual cost (USD) | D4: Cited from | E4: Note
A8: Total | C8: =SUM(C5:C7)

Sheet Shared
A1: Shared environment
A2: Azure retail list prices (pay-as-you-go) in southeastasia, USD, fetched 2026-09-28. Daily cost is the monthly cost spread over the year (x 12 / 365). Blue cells are inputs.
A4: # | B4: Component | C4: Azure service | D4: SKU / tier | E4: Unit | F4: Unit price (USD) | G4: Quantity | H4: Usage per month | I4: Monthly cost (USD) | J4: Daily cost (USD) | K4: Annual cost (USD) | L4: Cited from | M4: Price source | N4: Note | O4: Environment
A5: 1 | B5: PostgreSQL Flexible Server compute | C5: Azure Database for PostgreSQL | D5: Burstable B1ms | E5: 1 Hour | F5: 0.026 | G5: 1 | H5: 261 | I5: =F5*G5*H5*FxRate | J5: =I5*12/365 | K5: =I5*12 | L5: _bmad-output/planning-artifacts/architecture/architecture-ocrinvoicing-2026-09-28/ARCHITECTURE-SPINE.md AD-12 | M5: Azure Retail Prices API, Azure Database for PostgreSQL Flexible Server Burstable BS Series Compute / B1MS, southeastasia, USD per 1 Hour, meterId caa13868-6d59-5b82-ae7a-765904be9712, fetched 2026-09-28 | N5: AD-12 [ASSUMPTION] up-hours weekdays 09:00-21:00 SGT = ~261 h/month; stopped by hand otherwise | O5: Shared
A6: 2 | B6: PostgreSQL storage | C6: Azure Database for PostgreSQL | D6: Flex Server Storage | E6: 1 GB/Month | F6: 0.138 | G6: 32 | H6: 1 | I6: =F6*G6*H6*FxRate | J6: =I6*12/365 | K6: =I6*12 | L6: _bmad-output/planning-artifacts/architecture/architecture-ocrinvoicing-2026-09-28/ARCHITECTURE-SPINE.md AD-12 | M6: Azure Retail Prices API, Azure Database for PostgreSQL Flex Server Storage / Storage Data Stored, southeastasia, USD per 1 GB/Month, meterId 3dc8bdb7-8a94-5ffe-8836-6e80a540f61f, fetched 2026-09-28 | N6: 32 GB, billed while stopped; 7-day LRS backup within free allowance | O6: Shared
A7: 3 | B7: Document Intelligence | C7: Cognitive Services | D7: F0 (free) | E7: 1K pages | F7: 0 | G7: 1 | H7: 0.5 | I7: =F7*G7*H7*FxRate | J7: =I7*12/365 | K7: =I7*12 | L7: _bmad-output/planning-artifacts/architecture/architecture-ocrinvoicing-2026-09-28/ARCHITECTURE-SPINE.md AD-8 | M7: Free tier F0: $0 per AD-8; S0 would be $10 per 1,000 pages (not looked up) | N7: 500 pages/month cap shared by Dev and Prod | O7: Shared
A8: 4 | B8: ACS Email | C8: Email | D8: Basic, sent email | E8: 1 | F8: 0.00025 | G8: 1 | H8: 250 | I8: =F8*G8*H8*FxRate | J8: =I8*12/365 | K8: =I8*12 | L8: _bmad-output/planning-artifacts/architecture/architecture-ocrinvoicing-2026-09-28/ARCHITECTURE-SPINE.md AD-16 | M8: Azure Retail Prices API, Email / Basic Sent Email, southeastasia, USD per 1, meterId 91348e14-8d9f-561e-ba5e-06be5a2c7a89, fetched 2026-09-28 | N8: assumption: ~250 alert emails a month across Dev and Prod | O8: Shared
I9: =IF(F9="","",F9*G9*H9*FxRate) | J9: =IF(I9="","",I9*12/365) | K9: =IF(I9="","",I9*12) | O9: Shared
I10: =IF(F10="","",F10*G10*H10*FxRate) | J10: =IF(I10="","",I10*12/365) | K10: =IF(I10="","",I10*12) | O10: Shared
I11: =IF(F11="","",F11*G11*H11*FxRate) | J11: =IF(I11="","",I11*12/365) | K11: =IF(I11="","",I11*12) | O11: Shared
A12: Total | I12: =SUM(I5:I11) | J12: =SUM(J5:J11) | K12: =SUM(K5:K11)

Sheet Dev
A1: Dev environment
A2: Azure retail list prices (pay-as-you-go) in southeastasia, USD, fetched 2026-09-28. Daily cost is the monthly cost spread over the year (x 12 / 365). Blue cells are inputs.
A4: # | B4: Component | C4: Azure service | D4: SKU / tier | E4: Unit | F4: Unit price (USD) | G4: Quantity | H4: Usage per month | I4: Monthly cost (USD) | J4: Daily cost (USD) | K4: Annual cost (USD) | L4: Cited from | M4: Price source | N4: Note | O4: Environment
A5: 1 | B5: Stage queues | C5: Storage | D5: Queues v2 Standard LRS, Class 1 operations | E5: 10K | F5: 0.004 | G5: 1 | H5: 30 | I5: =F5*G5*H5*FxRate | J5: =I5*12/365 | K5: =I5*12 | L5: _bmad-output/planning-artifacts/architecture/architecture-ocrinvoicing-2026-09-28/ARCHITECTURE-SPINE.md AD-2 | M5: Azure Retail Prices API, Queues v2 / LRS Class 1 Operations, southeastasia, USD per 10K, meterId a7193db3-642b-4d6f-ad03-ed5f00153bbd, fetched 2026-09-28 | N5: assumption: ~300K ops/month from queue-trigger polling, matching AD-2's ~$0.12/month | O5: Dev
A6: 2 | B6: Blobs: images, corrections (30-day) | C6: Storage | D6: Block Blob v2 Hot LRS | E6: 1 GB/Month | F6: 0.02 | G6: 1 | H6: 1 | I6: =F6*G6*H6*FxRate | J6: =I6*12/365 | K6: =I6*12 | L6: _bmad-output/planning-artifacts/architecture/architecture-ocrinvoicing-2026-09-28/ARCHITECTURE-SPINE.md AD-15 | M6: Azure Retail Prices API, General Block Blob v2 / Hot LRS Data Stored, southeastasia, USD per 1 GB/Month, meterId fc203689-76e7-4fbe-86b9-968d73231c00, fetched 2026-09-28 | N6: assumption: 1 GB held under 30-day lifecycle (DI page cap bounds volume, AD-8) | O6: Dev
A7: 3 | B7: Tables: links, keys, reminders | C7: Storage | D7: Tables Standard LRS | E7: 1 GB/Month | F7: 0.045 | G7: 1 | H7: 0.1 | I7: =F7*G7*H7*FxRate | J7: =I7*12/365 | K7: =I7*12 | L7: _bmad-output/planning-artifacts/architecture/architecture-ocrinvoicing-2026-09-28/ARCHITECTURE-SPINE.md AD-6 | M7: Azure Retail Prices API, Tables / LRS Data Stored, southeastasia, USD per 1 GB/Month, meterId 3f2b1e1c-c886-4ec6-ad6f-dd0ef38819c9, fetched 2026-09-28 | N7: assumption: under 0.1 GB | O7: Dev
A8: 4 | B8: Key Vault | C8: Key Vault | D8: Standard, operations | E8: 10K | F8: 0.03 | G8: 1 | H8: 0.5 | I8: =F8*G8*H8*FxRate | J8: =I8*12/365 | K8: =I8*12 | L8: _bmad-output/planning-artifacts/architecture/architecture-ocrinvoicing-2026-09-28/ARCHITECTURE-SPINE.md AD-11 | M8: Azure Retail Prices API, Key Vault / Operations, southeastasia, USD per 10K, meterId 0f824807-2376-435c-95c9-f992b67a07b0, fetched 2026-09-28 | N8: assumption: ~5K secret reads a month | O8: Dev
A9: 5 | B9: Metric alerts | C9: Azure Monitor | D9: Alerts Metric Monitored, beyond first 10 free | E9: 1/Month | F9: 0.1 | G9: 5 | H9: 1 | I9: =F9*G9*H9*FxRate | J9: =I9*12/365 | K9: =I9*12 | L9: _bmad-output/planning-artifacts/architecture/architecture-ocrinvoicing-2026-09-28/ARCHITECTURE-SPINE.md AD-17 | M9: Azure Retail Prices API, Azure Monitor / Alerts Metric Monitored, southeastasia, USD per 1/Month, meterId 6860c782-bbcc-41ed-a218-fb308dd0942e, fetched 2026-09-28 | N9: assumption: ~10 time series per env (poison_message x 8 queues, stuck_invoices, di_pages_used_pct); first 10 per subscription free, half billed here | O9: Dev
A10: 6 | B10: Log Analytics + App Insights | C10: Log Analytics | D10: Analytics Logs ingestion, within 5 GB free | E10: 1 GB | F10: 0 | G10: 1 | H10: 2.4 | I10: =F10*G10*H10*FxRate | J10: =I10*12/365 | K10: =I10*12 | L10: _bmad-output/planning-artifacts/architecture/architecture-ocrinvoicing-2026-09-28/ARCHITECTURE-SPINE.md AD-17 | M10: Azure Retail Prices API, Log Analytics / Analytics Logs Data Ingestion, southeastasia, USD per 1 GB, meterId 7a4feecb-f730-49f8-a801-efe03d15b862, fetched 2026-09-28 | N10: 0.08 GB/day cap = 2.4 GB/month; both envs 4.8 GB, inside the 5 GB free tier (AD-17) | O10: Dev
I11: =IF(F11="","",F11*G11*H11*FxRate) | J11: =IF(I11="","",I11*12/365) | K11: =IF(I11="","",I11*12) | O11: Dev
I12: =IF(F12="","",F12*G12*H12*FxRate) | J12: =IF(I12="","",I12*12/365) | K12: =IF(I12="","",I12*12) | O12: Dev
I13: =IF(F13="","",F13*G13*H13*FxRate) | J13: =IF(I13="","",I13*12/365) | K13: =IF(I13="","",I13*12) | O13: Dev
A14: Total | I14: =SUM(I5:I13) | J14: =SUM(J5:J13) | K14: =SUM(K5:K13)

Sheet Prod
A1: Prod environment
A2: Azure retail list prices (pay-as-you-go) in southeastasia, USD, fetched 2026-09-28. Daily cost is the monthly cost spread over the year (x 12 / 365). Blue cells are inputs.
A4: # | B4: Component | C4: Azure service | D4: SKU / tier | E4: Unit | F4: Unit price (USD) | G4: Quantity | H4: Usage per month | I4: Monthly cost (USD) | J4: Daily cost (USD) | K4: Annual cost (USD) | L4: Cited from | M4: Price source | N4: Note | O4: Environment
A5: 1 | B5: Stage queues | C5: Storage | D5: Queues v2 Standard LRS, Class 1 operations | E5: 10K | F5: 0.004 | G5: 1 | H5: 30 | I5: =F5*G5*H5*FxRate | J5: =I5*12/365 | K5: =I5*12 | L5: _bmad-output/planning-artifacts/architecture/architecture-ocrinvoicing-2026-09-28/ARCHITECTURE-SPINE.md AD-2 | M5: Azure Retail Prices API, Queues v2 / LRS Class 1 Operations, southeastasia, USD per 10K, meterId a7193db3-642b-4d6f-ad03-ed5f00153bbd, fetched 2026-09-28 | N5: assumption: ~300K ops/month from queue-trigger polling, matching AD-2's ~$0.12/month | O5: Prod
A6: 2 | B6: Blobs: images, corrections (30-day) | C6: Storage | D6: Block Blob v2 Hot LRS | E6: 1 GB/Month | F6: 0.02 | G6: 2 | H6: 1 | I6: =F6*G6*H6*FxRate | J6: =I6*12/365 | K6: =I6*12 | L6: _bmad-output/planning-artifacts/architecture/architecture-ocrinvoicing-2026-09-28/ARCHITECTURE-SPINE.md AD-15 | M6: Azure Retail Prices API, General Block Blob v2 / Hot LRS Data Stored, southeastasia, USD per 1 GB/Month, meterId fc203689-76e7-4fbe-86b9-968d73231c00, fetched 2026-09-28 | N6: assumption: 2 GB held under 30-day lifecycle (DI page cap bounds volume, AD-8) | O6: Prod
A7: 3 | B7: Tables: links, keys, reminders | C7: Storage | D7: Tables Standard LRS | E7: 1 GB/Month | F7: 0.045 | G7: 1 | H7: 0.1 | I7: =F7*G7*H7*FxRate | J7: =I7*12/365 | K7: =I7*12 | L7: _bmad-output/planning-artifacts/architecture/architecture-ocrinvoicing-2026-09-28/ARCHITECTURE-SPINE.md AD-6 | M7: Azure Retail Prices API, Tables / LRS Data Stored, southeastasia, USD per 1 GB/Month, meterId 3f2b1e1c-c886-4ec6-ad6f-dd0ef38819c9, fetched 2026-09-28 | N7: assumption: under 0.1 GB | O7: Prod
A8: 4 | B8: Key Vault | C8: Key Vault | D8: Standard, operations | E8: 10K | F8: 0.03 | G8: 1 | H8: 0.5 | I8: =F8*G8*H8*FxRate | J8: =I8*12/365 | K8: =I8*12 | L8: _bmad-output/planning-artifacts/architecture/architecture-ocrinvoicing-2026-09-28/ARCHITECTURE-SPINE.md AD-11 | M8: Azure Retail Prices API, Key Vault / Operations, southeastasia, USD per 10K, meterId 0f824807-2376-435c-95c9-f992b67a07b0, fetched 2026-09-28 | N8: assumption: ~5K secret reads a month | O8: Prod
A9: 5 | B9: Metric alerts | C9: Azure Monitor | D9: Alerts Metric Monitored, beyond first 10 free | E9: 1/Month | F9: 0.1 | G9: 5 | H9: 1 | I9: =F9*G9*H9*FxRate | J9: =I9*12/365 | K9: =I9*12 | L9: _bmad-output/planning-artifacts/architecture/architecture-ocrinvoicing-2026-09-28/ARCHITECTURE-SPINE.md AD-17 | M9: Azure Retail Prices API, Azure Monitor / Alerts Metric Monitored, southeastasia, USD per 1/Month, meterId 6860c782-bbcc-41ed-a218-fb308dd0942e, fetched 2026-09-28 | N9: assumption: ~10 time series per env (poison_message x 8 queues, stuck_invoices, di_pages_used_pct); first 10 per subscription free, half billed here | O9: Prod
A10: 6 | B10: Log Analytics + App Insights | C10: Log Analytics | D10: Analytics Logs ingestion, within 5 GB free | E10: 1 GB | F10: 0 | G10: 1 | H10: 2.4 | I10: =F10*G10*H10*FxRate | J10: =I10*12/365 | K10: =I10*12 | L10: _bmad-output/planning-artifacts/architecture/architecture-ocrinvoicing-2026-09-28/ARCHITECTURE-SPINE.md AD-17 | M10: Azure Retail Prices API, Log Analytics / Analytics Logs Data Ingestion, southeastasia, USD per 1 GB, meterId 7a4feecb-f730-49f8-a801-efe03d15b862, fetched 2026-09-28 | N10: 0.08 GB/day cap = 2.4 GB/month; both envs 4.8 GB, inside the 5 GB free tier (AD-17) | O10: Prod
I11: =IF(F11="","",F11*G11*H11*FxRate) | J11: =IF(I11="","",I11*12/365) | K11: =IF(I11="","",I11*12) | O11: Prod
I12: =IF(F12="","",F12*G12*H12*FxRate) | J12: =IF(I12="","",I12*12/365) | K12: =IF(I12="","",I12*12) | O12: Prod
I13: =IF(F13="","",F13*G13*H13*FxRate) | J13: =IF(I13="","",I13*12/365) | K13: =IF(I13="","",I13*12) | O13: Prod
A14: Total | I14: =SUM(I5:I13) | J14: =SUM(J5:J13) | K14: =SUM(K5:K13)

Sheet Sources & Gaps
A1: Sources, assumptions and gaps
A3: Price basis
B4: Azure Retail Prices API list prices (pay-as-you-go, no discounts), region southeastasia, USD, fetched 2026-09-28.
B5: Rate card: Dj, in chat 2026-09-28: blended average day rate, updated 2026-09-28.
B6: Horizon: 5 years of run after go-live, run costs rising 0% a year.
A8: Gaps: not priced and not in any total
B9: Team size and days: proposed 2 people x 32 days; Dj has not set them.
B10: Run support mandays: proposed 12 a year; not set.
B11: Revenue or counted savings: none given, so no payback or ROI (SPEC says it removes manual keying of thousands of invoices a month).
B12: Contingency: 0% until Dj sets one.
B13: Delivery start date: not given, so epics and sprints are undated.
B14: Azure DevOps: assumed within the free tier (5 Basic users, 1 free Microsoft-hosted pipeline job); not priced.
B15: Actual cloud spend: the solution is not deployed yet (no babaloo-sea-lng-* resource groups in subscription Babaloo on 2026-09-28), so there is nothing to compare.
B16: Production volumes: F0 caps DI at 500 pages a month; SPEC's 'thousands a month' needs S0 (~$10 per 1,000 pages) and breaks P-2.
B17: Functions Flex on-demand: within the free 100K GB-s and 250K executions a month (AD-1), so no line is priced; the billed rate beyond that is $0.000037 per GB-s.
B18: Revenue: none given, so the Multi-Year sheet shows costs only.
A20: Assumptions and owner statements (not from the BMad artifacts)
B21: Team / Team member (blended): assumption: 2 people for 32 days (30 stories at ~1 story/day, AI-assisted, plus 2 days slack); Dj to confirm
B22: Support / Team member (blended): assumption: 1 day a month for patching, dependency upgrades, DB start/stop and alert triage; Dj to confirm
B23: Phase budget / planning changes (correct course): owner: Dj, 2026-09-28
B24: Phase budget / test design: owner: Dj, 2026-09-28
B25: Phase budget / merges, promotions & deploys: owner: Dj, 2026-09-28
B26: Phase budget / governance (Jules): owner: Dj, 2026-09-28
B27: Phase budget / architecture docs (Da Vinci): owner: Dj, 2026-09-28
B28: Phase budget / token reporting: owner: Dj, 2026-09-28
A30: Stamp: built 2026-09-28T22:52:18; sha256 of each cited file
B31: _bmad-output/planning-artifacts/architecture/architecture-ocrinvoicing-2026-09-28/ARCHITECTURE-SPINE.md 0772124ce4c6
B32: _bmad-output/planning-artifacts/epics.md ba1900bf6060
B33: _bmad/memory/agent-scrooge/rate-card.json 86a802068a37
